import { render, screen } from '@testing-library/react';
import { Provider } from 'react-redux';
import { vi, describe, it, expect, beforeAll, afterAll } from 'vitest';
import { store } from '../../store';
import ErrorBoundary from '../ErrorBoundary';

// Component that throws an error for testing
const ThrowError = ({ shouldThrow }: { shouldThrow: boolean }) => {
  if (shouldThrow) {
    throw new Error('Test error');
  }
  return <div>No error</div>;
};

const renderWithProvider = (component: React.ReactElement) => {
  return render(
    <Provider store={store}>
      {component}
    </Provider>
  );
};

describe('ErrorBoundary', () => {
  // Mock console.error to avoid noise in test output
  const originalError = console.error;
  beforeAll(() => {
    console.error = vi.fn();
  });

  afterAll(() => {
    console.error = originalError;
  });

  it('renders children when there is no error', () => {
    renderWithProvider(
      <ErrorBoundary>
        <ThrowError shouldThrow={false} />
      </ErrorBoundary>
    );

    expect(screen.getByText('No error')).toBeInTheDocument();
  });

  it('renders error UI when there is an error', () => {
    renderWithProvider(
      <ErrorBoundary>
        <ThrowError shouldThrow={true} />
      </ErrorBoundary>
    );

    expect(screen.getByText('Something went wrong')).toBeInTheDocument();
    expect(screen.getByText('Try again')).toBeInTheDocument();
    expect(screen.getByText('Reload page')).toBeInTheDocument();
  });

  it('renders custom fallback when provided', () => {
    const fallback = <div>Custom error message</div>;

    renderWithProvider(
      <ErrorBoundary fallback={fallback}>
        <ThrowError shouldThrow={true} />
      </ErrorBoundary>
    );

    expect(screen.getByText('Custom error message')).toBeInTheDocument();
  });
});